2019-12-07 23:18:01,725 ERROR: Exception on / [GET] [in c:\users\asus\shoplist\venv\lib\site-packages\flask\app.py:1891]
Traceback (most recent call last):
  File "c:\users\asus\shoplist\venv\lib\site-packages\sqlalchemy\util\_collections.py", line 1010, in __call__
    return self.registry[key]
KeyError: 23260

During handling of the above exception, another exception occurred:

Traceback (most recent call last):
  File "c:\users\asus\shoplist\venv\lib\site-packages\flask\app.py", line 2446, in wsgi_app
    response = self.full_dispatch_request()
  File "c:\users\asus\shoplist\venv\lib\site-packages\flask\app.py", line 1951, in full_dispatch_request
    rv = self.handle_user_exception(e)
  File "c:\users\asus\shoplist\venv\lib\site-packages\flask\app.py", line 1820, in handle_user_exception
    reraise(exc_type, exc_value, tb)
  File "c:\users\asus\shoplist\venv\lib\site-packages\flask\_compat.py", line 39, in reraise
    raise value
  File "c:\users\asus\shoplist\venv\lib\site-packages\flask\app.py", line 1947, in full_dispatch_request
    rv = self.preprocess_request()
  File "c:\users\asus\shoplist\venv\lib\site-packages\flask\app.py", line 2241, in preprocess_request
    rv = func()
  File "C:\Users\Asus\shoplist\app\main\routes.py", line 12, in before_request
    if current_user.is_authenticated:
  File "c:\users\asus\shoplist\venv\lib\site-packages\werkzeug\local.py", line 348, in __getattr__
    return getattr(self._get_current_object(), name)
  File "c:\users\asus\shoplist\venv\lib\site-packages\werkzeug\local.py", line 307, in _get_current_object
    return self.__local()
  File "c:\users\asus\shoplist\venv\lib\site-packages\flask_login\utils.py", line 26, in <lambda>
    current_user = LocalProxy(lambda: _get_user())
  File "c:\users\asus\shoplist\venv\lib\site-packages\flask_login\utils.py", line 335, in _get_user
    current_app.login_manager._load_user()
  File "c:\users\asus\shoplist\venv\lib\site-packages\flask_login\login_manager.py", line 359, in _load_user
    return self.reload_user()
  File "c:\users\asus\shoplist\venv\lib\site-packages\flask_login\login_manager.py", line 321, in reload_user
    user = self.user_callback(user_id)
  File "C:\Users\Asus\shoplist\app\models.py", line 98, in load_user
    return User.query.get(int(id))
  File "c:\users\asus\shoplist\venv\lib\site-packages\flask_sqlalchemy\__init__.py", line 519, in __get__
    return type.query_class(mapper, session=self.sa.session())
  File "c:\users\asus\shoplist\venv\lib\site-packages\sqlalchemy\orm\scoping.py", line 78, in __call__
    return self.registry()
  File "c:\users\asus\shoplist\venv\lib\site-packages\sqlalchemy\util\_collections.py", line 1012, in __call__
    return self.registry.setdefault(key, self.createfunc())
  File "c:\users\asus\shoplist\venv\lib\site-packages\sqlalchemy\orm\session.py", line 3225, in __call__
    return self.class_(**local_kw)
  File "c:\users\asus\shoplist\venv\lib\site-packages\flask_sqlalchemy\__init__.py", line 138, in __init__
    bind = options.pop('bind', None) or db.engine
  File "c:\users\asus\shoplist\venv\lib\site-packages\flask_sqlalchemy\__init__.py", line 937, in engine
    return self.get_engine()
  File "c:\users\asus\shoplist\venv\lib\site-packages\flask_sqlalchemy\__init__.py", line 956, in get_engine
    return connector.get_engine()
  File "c:\users\asus\shoplist\venv\lib\site-packages\flask_sqlalchemy\__init__.py", line 561, in get_engine
    self._engine = rv = self._sa.create_engine(sa_url, options)
  File "c:\users\asus\shoplist\venv\lib\site-packages\flask_sqlalchemy\__init__.py", line 966, in create_engine
    return sqlalchemy.create_engine(sa_url, **engine_opts)
  File "c:\users\asus\shoplist\venv\lib\site-packages\sqlalchemy\engine\__init__.py", line 479, in create_engine
    return strategy.create(*args, **kwargs)
  File "c:\users\asus\shoplist\venv\lib\site-packages\sqlalchemy\engine\strategies.py", line 87, in create
    dbapi = dialect_cls.dbapi(**dbapi_args)
  File "c:\users\asus\shoplist\venv\lib\site-packages\sqlalchemy\dialects\postgresql\psycopg2.py", line 737, in dbapi
    import psycopg2
ModuleNotFoundError: No module named 'psycopg2'
2019-12-07 23:20:04,547 INFO: Shoplist startup [in C:\Users\Asus\shoplist\app\__init__.py:57]
2019-12-07 23:20:09,076 ERROR: Exception on / [GET] [in c:\users\asus\shoplist\venv\lib\site-packages\flask\app.py:1891]
Traceback (most recent call last):
  File "c:\users\asus\shoplist\venv\lib\site-packages\sqlalchemy\engine\base.py", line 1246, in _execute_context
    cursor, statement, parameters, context
  File "c:\users\asus\shoplist\venv\lib\site-packages\sqlalchemy\engine\default.py", line 581, in do_execute
    cursor.execute(statement, parameters)
sqlite3.OperationalError: no such column: user.token

The above exception was the direct cause of the following exception:

Traceback (most recent call last):
  File "c:\users\asus\shoplist\venv\lib\site-packages\flask\app.py", line 2446, in wsgi_app
    response = self.full_dispatch_request()
  File "c:\users\asus\shoplist\venv\lib\site-packages\flask\app.py", line 1951, in full_dispatch_request
    rv = self.handle_user_exception(e)
  File "c:\users\asus\shoplist\venv\lib\site-packages\flask\app.py", line 1820, in handle_user_exception
    reraise(exc_type, exc_value, tb)
  File "c:\users\asus\shoplist\venv\lib\site-packages\flask\_compat.py", line 39, in reraise
    raise value
  File "c:\users\asus\shoplist\venv\lib\site-packages\flask\app.py", line 1947, in full_dispatch_request
    rv = self.preprocess_request()
  File "c:\users\asus\shoplist\venv\lib\site-packages\flask\app.py", line 2241, in preprocess_request
    rv = func()
  File "C:\Users\Asus\shoplist\app\main\routes.py", line 12, in before_request
    if current_user.is_authenticated:
  File "c:\users\asus\shoplist\venv\lib\site-packages\werkzeug\local.py", line 348, in __getattr__
    return getattr(self._get_current_object(), name)
  File "c:\users\asus\shoplist\venv\lib\site-packages\werkzeug\local.py", line 307, in _get_current_object
    return self.__local()
  File "c:\users\asus\shoplist\venv\lib\site-packages\flask_login\utils.py", line 26, in <lambda>
    current_user = LocalProxy(lambda: _get_user())
  File "c:\users\asus\shoplist\venv\lib\site-packages\flask_login\utils.py", line 335, in _get_user
    current_app.login_manager._load_user()
  File "c:\users\asus\shoplist\venv\lib\site-packages\flask_login\login_manager.py", line 359, in _load_user
    return self.reload_user()
  File "c:\users\asus\shoplist\venv\lib\site-packages\flask_login\login_manager.py", line 321, in reload_user
    user = self.user_callback(user_id)
  File "C:\Users\Asus\shoplist\app\models.py", line 98, in load_user
    return User.query.get(int(id))
  File "c:\users\asus\shoplist\venv\lib\site-packages\sqlalchemy\orm\query.py", line 982, in get
    return self._get_impl(ident, loading.load_on_pk_identity)
  File "c:\users\asus\shoplist\venv\lib\site-packages\sqlalchemy\orm\query.py", line 1094, in _get_impl
    return db_load_fn(self, primary_key_identity)
  File "c:\users\asus\shoplist\venv\lib\site-packages\sqlalchemy\orm\loading.py", line 284, in load_on_pk_identity
    return q.one()
  File "c:\users\asus\shoplist\venv\lib\site-packages\sqlalchemy\orm\query.py", line 3325, in one
    ret = self.one_or_none()
  File "c:\users\asus\shoplist\venv\lib\site-packages\sqlalchemy\orm\query.py", line 3294, in one_or_none
    ret = list(self)
  File "c:\users\asus\shoplist\venv\lib\site-packages\sqlalchemy\orm\query.py", line 3367, in __iter__
    return self._execute_and_instances(context)
  File "c:\users\asus\shoplist\venv\lib\site-packages\sqlalchemy\orm\query.py", line 3392, in _execute_and_instances
    result = conn.execute(querycontext.statement, self._params)
  File "c:\users\asus\shoplist\venv\lib\site-packages\sqlalchemy\engine\base.py", line 982, in execute
    return meth(self, multiparams, params)
  File "c:\users\asus\shoplist\venv\lib\site-packages\sqlalchemy\sql\elements.py", line 287, in _execute_on_connection
    return connection._execute_clauseelement(self, multiparams, params)
  File "c:\users\asus\shoplist\venv\lib\site-packages\sqlalchemy\engine\base.py", line 1101, in _execute_clauseelement
    distilled_params,
  File "c:\users\asus\shoplist\venv\lib\site-packages\sqlalchemy\engine\base.py", line 1250, in _execute_context
    e, statement, parameters, cursor, context
  File "c:\users\asus\shoplist\venv\lib\site-packages\sqlalchemy\engine\base.py", line 1476, in _handle_dbapi_exception
    util.raise_from_cause(sqlalchemy_exception, exc_info)
  File "c:\users\asus\shoplist\venv\lib\site-packages\sqlalchemy\util\compat.py", line 398, in raise_from_cause
    reraise(type(exception), exception, tb=exc_tb, cause=cause)
  File "c:\users\asus\shoplist\venv\lib\site-packages\sqlalchemy\util\compat.py", line 152, in reraise
    raise value.with_traceback(tb)
  File "c:\users\asus\shoplist\venv\lib\site-packages\sqlalchemy\engine\base.py", line 1246, in _execute_context
    cursor, statement, parameters, context
  File "c:\users\asus\shoplist\venv\lib\site-packages\sqlalchemy\engine\default.py", line 581, in do_execute
    cursor.execute(statement, parameters)
sqlalchemy.exc.OperationalError: (sqlite3.OperationalError) no such column: user.token
[SQL: SELECT user.id AS user_id, user.username AS user_username, user.email AS user_email, user.password AS user_password, user.token AS user_token, user.token_expiration AS user_token_expiration 
FROM user 
WHERE user.id = ?]
[parameters: (2,)]
(Background on this error at: http://sqlalche.me/e/e3q8)
2019-12-08 00:51:54,197 INFO: Shoplist startup [in C:\Users\Asus\shoplist\app\__init__.py:57]
